Workbook

Sheet Summary
A1: Insurance Order Entry - Whole Life Application: Test Case Suite
A2: Derived from documents 01-05. Executed status is 'Not Run' - the application was not reachable from the authoring environment. Pass/Fail columns update these counts live.
A4: Execution status
A5: Status | B5: Count | C5: % of total
A6: Not Run | B6: =COUNTIF('Test Cases'!$N:$N,A6) -> 257 | C6: =IF($B$11=0,0,B6/$B$11) -> 1
A7: Pass | B7: =COUNTIF('Test Cases'!$N:$N,A7) -> 0 | C7: =IF($B$11=0,0,B7/$B$11) -> 0
A8: Fail | B8: =COUNTIF('Test Cases'!$N:$N,A8) -> 0 | C8: =IF($B$11=0,0,B8/$B$11) -> 0
A9: Blocked | B9: =COUNTIF('Test Cases'!$N:$N,A9) -> 0 | C9: =IF($B$11=0,0,B9/$B$11) -> 0
A10: N/A | B10: =COUNTIF('Test Cases'!$N:$N,A10) -> 0 | C10: =IF($B$11=0,0,B10/$B$11) -> 0
A11: Total | B11: =SUM(B6:B10) -> 257
A14: By Module
A15: Module | B15: Total | C15: Critical | D15: High | E15: Medium | F15: Low
A16: Authentication | B16: =COUNTIF('Test Cases'!$B:$B,A16) -> 34 | C16: =COUNTIFS('Test Cases'!$B:$B,$A16,'Test Cases'!$F:$F,"Critical") -> 15 | D16: =COUNTIFS('Test Cases'!$B:$B,$A16,'Test Cases'!$F:$F,"High") -> 11 | E16: =COUNTIFS('Test Cases'!$B:$B,$A16,'Test Cases'!$F:$F,"Medium") -> 6 | F16: =COUNTIFS('Test Cases'!$B:$B,$A16,'Test Cases'!$F:$F,"Low") -> 2
A17: Dashboard | B17: =COUNTIF('Test Cases'!$B:$B,A17) -> 22 | C17: =COUNTIFS('Test Cases'!$B:$B,$A17,'Test Cases'!$F:$F,"Critical") -> 7 | D17: =COUNTIFS('Test Cases'!$B:$B,$A17,'Test Cases'!$F:$F,"High") -> 9 | E17: =COUNTIFS('Test Cases'!$B:$B,$A17,'Test Cases'!$F:$F,"Medium") -> 5 | F17: =COUNTIFS('Test Cases'!$B:$B,$A17,'Test Cases'!$F:$F,"Low") -> 1
A18: Client | B18: =COUNTIF('Test Cases'!$B:$B,A18) -> 25 | C18: =COUNTIFS('Test Cases'!$B:$B,$A18,'Test Cases'!$F:$F,"Critical") -> 13 | D18: =COUNTIFS('Test Cases'!$B:$B,$A18,'Test Cases'!$F:$F,"High") -> 8 | E18: =COUNTIFS('Test Cases'!$B:$B,$A18,'Test Cases'!$F:$F,"Medium") -> 3 | F18: =COUNTIFS('Test Cases'!$B:$B,$A18,'Test Cases'!$F:$F,"Low") -> 1
A19: Address & Contact | B19: =COUNTIF('Test Cases'!$B:$B,A19) -> 15 | C19: =COUNTIFS('Test Cases'!$B:$B,$A19,'Test Cases'!$F:$F,"Critical") -> 0 | D19: =COUNTIFS('Test Cases'!$B:$B,$A19,'Test Cases'!$F:$F,"High") -> 9 | E19: =COUNTIFS('Test Cases'!$B:$B,$A19,'Test Cases'!$F:$F,"Medium") -> 6 | F19: =COUNTIFS('Test Cases'!$B:$B,$A19,'Test Cases'!$F:$F,"Low") -> 0
A20: KYC / Financial / Compliance | B20: =COUNTIF('Test Cases'!$B:$B,A20) -> 21 | C20: =COUNTIFS('Test Cases'!$B:$B,$A20,'Test Cases'!$F:$F,"Critical") -> 9 | D20: =COUNTIFS('Test Cases'!$B:$B,$A20,'Test Cases'!$F:$F,"High") -> 11 | E20: =COUNTIFS('Test Cases'!$B:$B,$A20,'Test Cases'!$F:$F,"Medium") -> 1 | F20: =COUNTIFS('Test Cases'!$B:$B,$A20,'Test Cases'!$F:$F,"Low") -> 0
A21: Product | B21: =COUNTIF('Test Cases'!$B:$B,A21) -> 18 | C21: =COUNTIFS('Test Cases'!$B:$B,$A21,'Test Cases'!$F:$F,"Critical") -> 11 | D21: =COUNTIFS('Test Cases'!$B:$B,$A21,'Test Cases'!$F:$F,"High") -> 6 | E21: =COUNTIFS('Test Cases'!$B:$B,$A21,'Test Cases'!$F:$F,"Medium") -> 1 | F21: =COUNTIFS('Test Cases'!$B:$B,$A21,'Test Cases'!$F:$F,"Low") -> 0
A22: Riders | B22: =COUNTIF('Test Cases'!$B:$B,A22) -> 18 | C22: =COUNTIFS('Test Cases'!$B:$B,$A22,'Test Cases'!$F:$F,"Critical") -> 10 | D22: =COUNTIFS('Test Cases'!$B:$B,$A22,'Test Cases'!$F:$F,"High") -> 6 | E22: =COUNTIFS('Test Cases'!$B:$B,$A22,'Test Cases'!$F:$F,"Medium") -> 2 | F22: =COUNTIFS('Test Cases'!$B:$B,$A22,'Test Cases'!$F:$F,"Low") -> 0
A23: Beneficiaries | B23: =COUNTIF('Test Cases'!$B:$B,A23) -> 25 | C23: =COUNTIFS('Test Cases'!$B:$B,$A23,'Test Cases'!$F:$F,"Critical") -> 14 | D23: =COUNTIFS('Test Cases'!$B:$B,$A23,'Test Cases'!$F:$F,"High") -> 8 | E23: =COUNTIFS('Test Cases'!$B:$B,$A23,'Test Cases'!$F:$F,"Medium") -> 3 | F23: =COUNTIFS('Test Cases'!$B:$B,$A23,'Test Cases'!$F:$F,"Low") -> 0
A24: Documents | B24: =COUNTIF('Test Cases'!$B:$B,A24) -> 19 | C24: =COUNTIFS('Test Cases'!$B:$B,$A24,'Test Cases'!$F:$F,"Critical") -> 8 | D24: =COUNTIFS('Test Cases'!$B:$B,$A24,'Test Cases'!$F:$F,"High") -> 6 | E24: =COUNTIFS('Test Cases'!$B:$B,$A24,'Test Cases'!$F:$F,"Medium") -> 4 | F24: =COUNTIFS('Test Cases'!$B:$B,$A24,'Test Cases'!$F:$F,"Low") -> 1
A25: Review / Submit | B25: =COUNTIF('Test Cases'!$B:$B,A25) -> 21 | C25: =COUNTIFS('Test Cases'!$B:$B,$A25,'Test Cases'!$F:$F,"Critical") -> 8 | D25: =COUNTIFS('Test Cases'!$B:$B,$A25,'Test Cases'!$F:$F,"High") -> 11 | E25: =COUNTIFS('Test Cases'!$B:$B,$A25,'Test Cases'!$F:$F,"Medium") -> 2 | F25: =COUNTIFS('Test Cases'!$B:$B,$A25,'Test Cases'!$F:$F,"Low") -> 0
A26: Status Tracking | B26: =COUNTIF('Test Cases'!$B:$B,A26) -> 9 | C26: =COUNTIFS('Test Cases'!$B:$B,$A26,'Test Cases'!$F:$F,"Critical") -> 5 | D26: =COUNTIFS('Test Cases'!$B:$B,$A26,'Test Cases'!$F:$F,"High") -> 2 | E26: =COUNTIFS('Test Cases'!$B:$B,$A26,'Test Cases'!$F:$F,"Medium") -> 2 | F26: =COUNTIFS('Test Cases'!$B:$B,$A26,'Test Cases'!$F:$F,"Low") -> 0
A27: Database | B27: =COUNTIF('Test Cases'!$B:$B,A27) -> 5 | C27: =COUNTIFS('Test Cases'!$B:$B,$A27,'Test Cases'!$F:$F,"Critical") -> 0 | D27: =COUNTIFS('Test Cases'!$B:$B,$A27,'Test Cases'!$F:$F,"High") -> 4 | E27: =COUNTIFS('Test Cases'!$B:$B,$A27,'Test Cases'!$F:$F,"Medium") -> 1 | F27: =COUNTIFS('Test Cases'!$B:$B,$A27,'Test Cases'!$F:$F,"Low") -> 0
... A31: Cross-cutting | B31: =COUNTIF('Test Cases'!$B:$B,A31) -> 6 | C31: =COUNTIFS('Test Cases'!$B:$B,$A31,'Test Cases'!$F:$F,"Critical") -> 0 | D31: =COUNTIFS('Test Cases'!$B:$B,$A31,'Test Cases'!$F:$F,"High") -> 0 | E31: =COUNTIFS('Test Cases'!$B:$B,$A31,'Test Cases'!$F:$F,"Medium") -> 5 | F31: =COUNTIFS('Test Cases'!$B:$B,$A31,'Test Cases'!$F:$F,"Low") -> 1
A32: Total | B32: =SUM(B16:B31) -> 257 | C32: =SUM(C16:C31) -> 105 | D32: =SUM(D16:D31) -> 99 | E32: =SUM(E16:E31) -> 45 | F32: =SUM(F16:F31) -> 8
A35: By Layer
A36: Layer | B36: Total | C36: Critical | D36: High | E36: Medium | F36: Low
A37: UI | B37: =COUNTIF('Test Cases'!$C:$C,A37) -> 182 | C37: =COUNTIFS('Test Cases'!$C:$C,$A37,'Test Cases'!$F:$F,"Critical") -> 66 | D37: =COUNTIFS('Test Cases'!$C:$C,$A37,'Test Cases'!$F:$F,"High") -> 71 | E37: =COUNTIFS('Test Cases'!$C:$C,$A37,'Test Cases'!$F:$F,"Medium") -> 39 | F37: =COUNTIFS('Test Cases'!$C:$C,$A37,'Test Cases'!$F:$F,"Low") -> 6
A38: API | B38: =COUNTIF('Test Cases'!$C:$C,A38) -> 62 | C38: =COUNTIFS('Test Cases'!$C:$C,$A38,'Test Cases'!$F:$F,"Critical") -> 34 | D38: =COUNTIFS('Test Cases'!$C:$C,$A38,'Test Cases'!$F:$F,"High") -> 21 | E38: =COUNTIFS('Test Cases'!$C:$C,$A38,'Test Cases'!$F:$F,"Medium") -> 5 | F38: =COUNTIFS('Test Cases'!$C:$C,$A38,'Test Cases'!$F:$F,"Low") -> 2
A39: DB | B39: =COUNTIF('Test Cases'!$C:$C,A39) -> 5 | C39: =COUNTIFS('Test Cases'!$C:$C,$A39,'Test Cases'!$F:$F,"Critical") -> 0 | D39: =COUNTIFS('Test Cases'!$C:$C,$A39,'Test Cases'!$F:$F,"High") -> 4 | E39: =COUNTIFS('Test Cases'!$C:$C,$A39,'Test Cases'!$F:$F,"Medium") -> 1 | F39: =COUNTIFS('Test Cases'!$C:$C,$A39,'Test Cases'!$F:$F,"Low") -> 0
A40: UI+API | B40: =COUNTIF('Test Cases'!$C:$C,A40) -> 8 | C40: =COUNTIFS('Test Cases'!$C:$C,$A40,'Test Cases'!$F:$F,"Critical") -> 5 | D40: =COUNTIFS('Test Cases'!$C:$C,$A40,'Test Cases'!$F:$F,"High") -> 3 | E40: =COUNTIFS('Test Cases'!$C:$C,$A40,'Test Cases'!$F:$F,"Medium") -> 0 | F40: =COUNTIFS('Test Cases'!$C:$C,$A40,'Test Cases'!$F:$F,"Low") -> 0
A41: Total | B41: =SUM(B37:B40) -> 257 | C41: =SUM(C37:C40) -> 105 | D41: =SUM(D37:D40) -> 99 | E41: =SUM(E37:E40) -> 45 | F41: =SUM(F37:F40) -> 8
A44: By Test Type
A45: Test Type | B45: Total | C45: Critical | D45: High | E45: Medium | F45: Low
A46: Positive | B46: =COUNTIF('Test Cases'!$E:$E,A46) -> 93 | C46: =COUNTIFS('Test Cases'!$E:$E,$A46,'Test Cases'!$F:$F,"Critical") -> 28 | D46: =COUNTIFS('Test Cases'!$E:$E,$A46,'Test Cases'!$F:$F,"High") -> 38 | E46: =COUNTIFS('Test Cases'!$E:$E,$A46,'Test Cases'!$F:$F,"Medium") -> 23 | F46: =COUNTIFS('Test Cases'!$E:$E,$A46,'Test Cases'!$F:$F,"Low") -> 4
A47: Negative | B47: =COUNTIF('Test Cases'!$E:$E,A47) -> 89 | C47: =COUNTIFS('Test Cases'!$E:$E,$A47,'Test Cases'!$F:$F,"Critical") -> 42 | D47: =COUNTIFS('Test Cases'!$E:$E,$A47,'Test Cases'!$F:$F,"High") -> 30 | E47: =COUNTIFS('Test Cases'!$E:$E,$A47,'Test Cases'!$F:$F,"Medium") -> 15 | F47: =COUNTIFS('Test Cases'!$E:$E,$A47,'Test Cases'!$F:$F,"Low") -> 2
A48: Boundary | B48: =COUNTIF('Test Cases'!$E:$E,A48) -> 22 | C48: =COUNTIFS('Test Cases'!$E:$E,$A48,'Test Cases'!$F:$F,"Critical") -> 14 | D48: =COUNTIFS('Test Cases'!$E:$E,$A48,'Test Cases'!$F:$F,"High") -> 4 | E48: =COUNTIFS('Test Cases'!$E:$E,$A48,'Test Cases'!$F:$F,"Medium") -> 2 | F48: =COUNTIFS('Test Cases'!$E:$E,$A48,'Test Cases'!$F:$F,"Low") -> 2
A49: End-to-End | B49: =COUNTIF('Test Cases'!$E:$E,A49) -> 8 | C49: =COUNTIFS('Test Cases'!$E:$E,$A49,'Test Cases'!$F:$F,"Critical") -> 5 | D49: =COUNTIFS('Test Cases'!$E:$E,$A49,'Test Cases'!$F:$F,"High") -> 3 | E49: =COUNTIFS('Test Cases'!$E:$E,$A49,'Test Cases'!$F:$F,"Medium") -> 0 | F49: =COUNTIFS('Test Cases'!$E:$E,$A49,'Test Cases'!$F:$F,"Low") -> 0
A50: Security | B50: =COUNTIF('Test Cases'!$E:$E,A50) -> 21 | C50: =COUNTIFS('Test Cases'!$E:$E,$A50,'Test Cases'!$F:$F,"Critical") -> 11 | D50: =COUNTIFS('Test Cases'!$E:$E,$A50,'Test Cases'!$F:$F,"High") -> 9 | E50: =COUNTIFS('Test Cases'!$E:$E,$A50,'Test Cases'!$F:$F,"Medium") -> 1 | F50: =COUNTIFS('Test Cases'!$E:$E,$A50,'Test Cases'!$F:$F,"Low") -> 0
...

Sheet Test Cases
A1: TC ID | B1: Module | C1: Layer | D1: Test Scenario | E1: Test Type | F1: Priority | G1: Preconditions | H1: User / Test Data | I1: Test Steps | J1: Expected Result | K1: Risk Ref | L1: Dependency / Open Item | M1: Source Document | N1: Status | O1: Actual Result | P1: Defect ID | Q1: Evidence | R1: Executed By | S1: Executed On
A2: AUTH-001 | B2: Authentication | C2: UI | D2: Valid agent login lands on dashboard | E2: Positive | F2: Critical | G2: App reachable; not logged in | H2: agent.valid@insurance.test / Password@123 | I2: 1. Open /login 2. Enter valid email and password 3. Click Login | J2: User is authenticated and redirected to /dashboard; agent identity shown; no error displayed. | K2: R01 | M2: 02 Workflow; 03 Strategy s3-4; 04 Risk R01 | N2: Not Run
A3: AUTH-002 | B3: Authentication | C3: UI | D3: Login page renders all controls | E3: Positive | F3: Medium | G3: App reachable | I3: 1. Open /login | J3: Email field, password field (masked) and Login button are visible and enabled; page title/branding correct; no console errors. | K3: R01 | M3: 02 Workflow; 03 Strategy s3-4; 04 Risk R01 | N3: Not Run
A4: AUTH-003 | B4: Authentication | C4: UI | D4: Login with Enter key | E4: Positive | F4: Low | G4: On /login | H4: agent.valid@insurance.test / Password@123 | I4: 1. Enter credentials 2. Press Enter in password field | J4: Form submits and login succeeds same as button click. | K4: R01 | M4: 02 Workflow; 03 Strategy s3-4; 04 Risk R01 | N4: Not Run
A5: AUTH-004 | B5: Authentication | C5: UI | D5: Logout ends session | E5: Positive | F5: Critical | G5: Logged in as valid agent | H5: agent.valid@insurance.test | I5: 1. Click Logout 2. Observe redirect 3. Browser Back 4. Open /dashboard directly | J5: Redirected to /login; Back/direct URL do not show protected data and force /login; session/token cleared. | K5: R01 | M5: 02 Workflow; 03 Strategy s3-4; 04 Risk R01 | N5: Not Run
A6: AUTH-005 | B6: Authentication | C6: UI | D6: Session survives page refresh | E6: Positive | F6: Medium | G6: Logged in | H6: agent.valid@insurance.test | I6: 1. On /dashboard press F5 | J6: User remains logged in; dashboard reloads with same data. | K6: R01 | M6: 02 Workflow; 03 Strategy s3-4; 04 Risk R01 | N6: Not Run
A7: AUTH-006 | B7: Authentication | C7: UI | D7: Invalid password rejected | E7: Negative | F7: Critical | G7: On /login | H7: agent.valid@insurance.test / WrongPass@1 | I7: 1. Enter valid email and wrong password 2. Click Login | J7: Login refused with a clear generic 'invalid credentials' message; user stays on /login; no session created. | K7: R01 | M7: 02 Workflow; 03 Strategy s3-4; 04 Risk R01 | N7: Not Run
A8: AUTH-007 | B8: Authentication | C8: UI | D8: Unregistered email rejected | E8: Negative | F8: Critical | G8: On /login | H8: nouser@insurance.test / Password@123 | I8: 1. Enter unknown email and any password 2. Click Login | J8: Login refused with same generic message as wrong password (no user enumeration). | K8: R01 | M8: 02 Workflow; 03 Strategy s3-4; 04 Risk R01 | N8: Not Run
A9: AUTH-008 | B9: Authentication | C9: UI | D9: Blank email and password | E9: Negative | F9: High | G9: On /login | H9: both empty | I9: 1. Click Login with both fields empty | J9: Required-field validation shown for both fields; no request authenticates; stays on /login. | K9: R01 | M9: 02 Workflow; 03 Strategy s3-4; 04 Risk R01 | N9: Not Run
A10: AUTH-009 | B10: Authentication | C10: UI | D10: Blank email only | E10: Negative | F10: High | G10: On /login | H10: password Password@123 | I10: 1. Leave email empty, enter password 2. Click Login | J10: Email required message shown; login not attempted. | K10: R01 | M10: 02 Workflow; 03 Strategy s3-4; 04 Risk R01 | N10: Not Run
A11: AUTH-010 | B11: Authentication | C11: UI | D11: Blank password only | E11: Negative | F11: High | G11: On /login | H11: agent.valid@insurance.test | I11: 1. Enter email, leave password empty 2. Click Login | J11: Password required message shown; login not attempted. | K11: R01 | M11: 02 Workflow; 03 Strategy s3-4; 04 Risk R01 | N11: Not Run
A12: AUTH-011 | B12: Authentication | C12: UI | D12: Malformed email format | E12: Negative | F12: Medium | G12: On /login | H12: agent.valid@ ; agent.valid ; @insurance.test | I12: 1. Enter each malformed email with a password 2. Click Login | J12: Format validation or generic failure; no authentication; no server error. | K12: R01 | M12: 02 Workflow; 03 Strategy s3-4; 04 Risk R01 | N12: Not Run
A13: AUTH-012 | B13: Authentication | C13: UI | D13: Locked account shows correct locked message | E13: Negative | F13: Critical | G13: Account locked by seed | H13: agent.locked@insurance.test / Password@123 | I13: 1. Login with locked user and correct password | J13: Login blocked with an explicit 'account locked' style message (not 'invalid credentials' and not a success); no session created. Risk: incorrect locked-user message. | K13: R01 | L13: D-02 | M13: 02 Workflow; 03 Strategy s3-4; 04 Risk R01 | N13: Not Run
A14: AUTH-013 | B14: Authentication | C14: UI | D14: Failed-attempt lockout triggers after threshold | E14: Negative | F14: Critical | G14: Fresh unlocked learner account (use learner pool, not shared agent.valid) | H14: learner001@insurance.test / wrong password | I14: 1. Submit wrong password repeatedly, counting attempts 2. Note the attempt at which lock/lock-message appears 3. Submit CORRECT password afterwards | J14: Account is locked at the documented threshold; subsequent correct password is also rejected with locked message. Record threshold (not documented). | K14: R01 | L14: D-02 / Clarif-2 | M14: 02 Workflow; 03 Strategy s3-4; 04 Risk R01 | N14: Not Run
A15: AUTH-014 | B15: Authentication | C15: UI | D15: Failed attempts below threshold do not lock | E15: Boundary | F15: High | G15: Fresh learner account | H15: learner002 with (threshold-1) wrong attempts then correct password | I15: 1. Fail (threshold-1) times 2. Login with correct password | J15: Login succeeds and counter resets. | K15: R01 | L15: Threshold TBC | M15: 02 Workflow; 03 Strategy s3-4; 04 Risk R01 | N15: Not Run
A16: AUTH-015 | B16: Authentication | C16: UI | D16: Direct access /dashboard when logged out | E16: Negative | F16: Critical | G16: No session | I16: 1. Open /dashboard directly | J16: Redirected to /login; no dashboard data rendered. | K16: R01 | M16: 02 Workflow; 03 Strategy s3-4; 04 Risk R01 | N16: Not Run
A17: AUTH-016 | B17: Authentication | C17: UI | D17: Direct access to application routes when logged out | E17: Negative | F17: Critical | G17: No session; a known applicationId | H17: /applications/new ; /applications/:id ; /client ; /documents ; /review ; /status | I17: 1. Open each route directly without logging in | J17: Every protected route redirects to /login (or 401/403 page); no application data leaked. | K17: R01 | M17: 02 Workflow; 03 Strategy s3-4; 04 Risk R01 | N17: Not Run
A18: AUTH-017 | B18: Authentication | C18: UI | D18: Password field masked; not exposed in URL | E18: Security | F18: High | G18: On /login | I18: 1. Type password 2. Submit 3. Inspect URL, browser history and DOM attribute | J18: Password displayed masked; never appears in URL/query string or history. | K18: R01 | M18: 02 Workflow; 03 Strategy s3-4; 04 Risk R01 | N18: Not Run
A19: AUTH-018 | B19: Authentication | C19: UI | D19: Password policy consistent across entry points | E19: Negative | F19: Medium | G19: Where a password create/change flow exists | H19: weak passwords e.g. '123', 'password' | I19: 1. Locate any password set/reset/change UI 2. Try weak vs policy-compliant values | J19: Same policy applied everywhere (risk: inconsistent password policy). If no such flow exists, record N/A. | K19: R01 | L19: Not documented | M19: 02 Workflow; 03 Strategy s3-4; 04 Risk R01 | N19: Not Run
A20: AUTH-019 | B20: Authentication | C20: UI | D20: Login error messages do not leak details | E20: Security | F20: High | G20: On /login | H20: invalid credentials variants | I20: 1. Compare message/response time/HTTP status for unknown user vs wrong password vs locked | J20: No stack traces, SQL errors or internal info; messages appropriate; no unintended user enumeration beyond locked message. | K20: R01 | M20: 02 Workflow; 03 Strategy s3-4; 04 Risk R01 | N20: Not Run
A21: AUTH-020 | B21: Authentication | C21: UI | D21: SQL injection / script payload in login fields | E21: Security | F21: High | G21: On /login | H21: ' OR '1'='1 ; <script>alert(1)</script> | I21: 1. Enter payload in email and password 2. Submit | J21: Login rejected; no script execution; no DB error shown; no 500. | K21: R01 | M21: 02 Workflow; 03 Strategy s3-4; 04 Risk R01 | N21: Not Run
A22: AUTH-021 | B22: Authentication | C22: UI | D22: Email case and whitespace handling | E22: Boundary | F22: Low | G22: On /login | H22: AGENT.VALID@INSURANCE.TEST ; ' agent.valid@insurance.test ' | I22: 1. Login with upper-case email 2. Login with leading/trailing spaces | J22: Behavior is consistent and documented (accept after normalisation or reject with clear message); no crash. | K22: R01 | L22: Clarify | M22: 02 Workflow; 03 Strategy s3-4; 04 Risk R01 | N22: Not Run
A23: AUTH-022 | B23: Authentication | C23: UI | D23: Learner pool user can login (sample) | E23: Positive | F23: Medium | G23: Learner accounts provisioned | H23: learner001 and learner030 / Password@123 | I23: 1. Login as learner001 2. Logout 3. Login as learner030 | J23: Both log in successfully to own empty/seeded dashboard. | K23: R01 | M23: 02 Workflow; 03 Strategy s3-4; 04 Risk R01 | N23: Not Run
A24: AUTH-023 | B24: Authentication | C24: UI | D24: Two users logged in parallel are isolated | E24: Security | F24: High | G24: Two browser contexts | H24: agent.valid@insurance.test and agent.draft@insurance.test | I24: 1. Login as user A in context 1 2. Login as user B in context 2 3. Compare dashboards; refresh both | J24: Each context shows only its own user/session data; no cross-session bleed. | K24: R01 R02 | M24: 02 Workflow; 03 Strategy s3-4; 04 Risk R01 | N24: Not Run
A25: AUTH-024 | B25: Authentication | C25: UI | D25: MFA / OTP login | E25: Positive | F25: High | G25: MFA user and OTP simulation available | H25: MFA account TBC | I25: 1. Login as MFA user 2. Enter OTP | J25: Valid OTP grants access; invalid/expired OTP rejected. | K25: R01 | L25: D-02 (MFA user + OTP mechanism not supplied) - BLOCKED | M25: 02 Workflow; 03 Strategy s3-4; 04 Risk R01 | N25: Not Run
A26: AUTH-025 | B26: Authentication | C26: UI | D26: Session timeout / idle expiry | E26: Negative | F26: Medium | G26: Logged in | I26: 1. Stay idle for configured timeout 2. Perform an action | J26: Session expires per policy and user is sent to /login without data loss prompt issues. | K26: R01 | L26: Timeout not documented | M26: 02 Workflow; 03 Strategy s3-4; 04 Risk R01 | N26: Not Run
A27: AAPI-001 | B27: Authentication | C27: API | D27: API call without X-API-Key | E27: Negative | F27: Critical | G27: API base http://34.93.145.116:8081/api | H27: no header | I27: 1. Call any protected endpoint (e.g. GET /api/applications) without X-API-Key | J27: 401/403 returned with standard error body; no data. | K27: R01 | M27: 03 Strategy (API layer); 04 Risk R01. Endpoint paths assumed - confirm with contract (D-05) | N27: Not Run
A28: AAPI-002 | B28: Authentication | C28: API | D28: API call with invalid X-API-Key | E28: Negative | F28: Critical | H28: X-API-Key: invalid-token | I28: 1. Call protected endpoint with wrong key | J28: 401/403; no data; no stack trace. | K28: R01 | M28: 03 Strategy (API layer); 04 Risk R01. Endpoint paths assumed - confirm with contract (D-05) | N28: Not Run
A29: AAPI-003 | B29: Authentication | C29: API | D29: API call with valid X-API-Key | E29: Positive | F29: Critical | H29: X-API-Key: qa-insurance-demo-token-123 | I29: 1. Call protected endpoint with valid key | J29: 200 with documented JSON schema. | K29: R01 | M29: 03 Strategy (API layer); 04 Risk R01. Endpoint paths assumed - confirm with contract (D-05) | N29: Not Run
A30: AAPI-004 | B30: Authentication | C30: API | D30: Login API valid credentials | E30: Positive | F30: Critical | H30: agent.valid@insurance.test / Password@123 | I30: 1. POST login service with valid credentials | J30: 200; session/token returned; user profile consistent with UI. | K30: R01 | L30: Path TBC | M30: 03 Strategy (API layer); 04 Risk R01. Endpoint paths assumed - confirm with contract (D-05) | N30: Not Run
A31: AAPI-005 | B31: Authentication | C31: API | D31: Login API invalid credentials | E31: Negative | F31: Critical | H31: agent.valid@insurance.test / wrong | I31: 1. POST login with wrong password | J31: 401 with generic error; no token. | K31: R01 | L31: Path TBC | M31: 03 Strategy (API layer); 04 Risk R01. Endpoint paths assumed - confirm with contract (D-05) | N31: Not Run
A32: AAPI-006 | B32: Authentication | C32: API | D32: Login API locked user | E32: Negative | F32: Critical | H32: agent.locked@insurance.test / Password@123 | I32: 1. POST login for locked user | J32: Rejected with locked indication (403/423 or documented); no token. Compare to UI message. | K32: R01 | L32: Path TBC | M32: 03 Strategy (API layer); 04 Risk R01. Endpoint paths assumed - confirm with contract (D-05) | N32: Not Run
A33: AAPI-007 | B33: Authentication | C33: API | D33: Login API blank / malformed payload | E33: Negative | F33: High | H33: {} ; missing password ; wrong types ; invalid JSON | I33: 1. POST each invalid payload | J33: 400/422 with field-level error; no 500. | K33: R01 | L33: Path TBC | M33: 03 Strategy (API layer); 04 Risk R01. Endpoint paths assumed - confirm with contract (D-05) | N33: Not Run
A34: AAPI-008 | B34: Authentication | C34: API | D34: Protected endpoint with user token but other user's data | E34: Security | F34: Critical | G34: Two users' tokens | H34: agent.valid@insurance.test token vs agent.draft@insurance.test application | I34: 1. Using user A auth, request user B's application by id | J34: 403/404; no data from user B (see IDOR cases). | K34: R01 R02 | M34: 03 Strategy (API layer); 04 Risk R01. Endpoint paths assumed - confirm with contract (D-05) | N34: Not Run
A35: AAPI-009 | B35: Authentication | C35: API | D35: Logout API invalidates session | E35: Positive | F35: High | G35: Logged in via API | I35: 1. Call logout 2. Reuse previous token | J35: Reused token rejected 401. | K35: R01 | L35: Path TBC | M35: 03 Strategy (API layer); 04 Risk R01. Endpoint paths assumed - confirm with contract (D-05) | N35: Not Run
A36: DASH-001 | B36: Dashboard | C36: UI | D36: Dashboard loads with summary and application list | E36: Positive | F36: High | G36: Logged in | H36: agent.valid@insurance.test | I36: 1. Login 2. Observe /dashboard | J36: Applications table/cards, status summaries and 'New Application' action visible; no console/network errors. | K36: R02 | M36: 02 Workflow; 03 Strategy s3; 04 Risk R02 | N36: Not Run
A37: DASH-002 | B37: Dashboard | C37: UI | D37: Empty state for user with no applications | E37: Positive | F37: High | G37: Fresh user | H37: agent.new@insurance.test | I37: 1. Login as agent.new | J37: Meaningful empty-state message and New Application CTA; no broken table or errors. | K37: R02 | M37: 02 Workflow; 03 Strategy s3; 04 Risk R02 | N37: Not Run
A38: DASH-003 | B38: Dashboard | C38: UI | D38: Draft scenario user sees draft application(s) | E38: Positive | F38: High | G38: Seeded draft | H38: agent.draft@insurance.test | I38: 1. Login as agent.draft | J38: At least one application with status Draft and a Resume action. | K38: R02 | L38: D-03 | M38: 02 Workflow; 03 Strategy s3; 04 Risk R02 | N38: Not Run
A39: DASH-004 | B39: Dashboard | C39: UI | D39: Submitted scenario user sees submitted application(s) | E39: Positive | F39: High | G39: Seeded submitted | H39: agent.submitted@insurance.test | I39: 1. Login as agent.submitted | J39: Submitted application listed with reference number and Submitted status. | K39: R02 R12 | L39: D-03 | M39: 02 Workflow; 03 Strategy s3; 04 Risk R02 | N39: Not Run
A40: DASH-005 | B40: Dashboard | C40: UI | D40: New Application button opens /applications/new | E40: Positive | F40: Critical | G40: Logged in | H40: agent.valid@insurance.test | I40: 1. Click New Application | J40: Navigates to /applications/new then to client step; draft application id created. | K40: R02 | M40: 02 Workflow; 03 Strategy s3; 04 Risk R02 | N40: Not Run
...

Sheet Test Data & Env
A1: Item | B1: Value | C1: Purpose / Notes
A2: Application URL | B2: http://34.93.145.116:8081/login | C2: UI entry point (plain HTTP)
A3: API base URL | B3: http://34.93.145.116:8081/api | C3: Endpoint paths in API cases are assumed; confirm against contract (D-05)
A4: API auth header | B4: X-API-Key: qa-insurance-demo-token-123 | C4: Demo key supplied by client
A5: Common password | B5: Password@123 | C5: All seeded users
A6: agent.valid@insurance.test | B6: Valid user | C6: Primary happy-path / regression
A7: agent.new@insurance.test | B7: Fresh user | C7: Empty dashboard / first-run
A8: agent.draft@insurance.test | B8: Draft user | C8: Draft resume scenarios
A9: agent.submitted@insurance.test | B9: Submitted user | C9: Read-only, status and reference checks
A10: agent.locked@insurance.test | B10: Locked user | C10: Negative locked-login scenario
A11: learner001 ... learner030 @insurance.test | B11: Learner pool | C11: Use for destructive cases (lockout threshold, parallel sessions). Do not use agent.valid for lockout tests.
A12: Age boundary DOBs | B12: Compute from execution date | C12: 18y exact, 17y364d, 65y exact, 65y+1d, 66y, future, today
... A14: Account hygiene | B14: Tests that create/submit applications consume seed state | C14: Agree reset owner/procedure (Clarif-4)

Sheet Traceability
A1: Risk ID | B1: Module (Doc 04) | C1: Priority | D1: Risk | E1: # Test Cases | F1: Covering Test Case IDs
A2: R01 | B2: Authentication | C2: Critical | D2: Unauthorized access, failed valid login, wrong locked message, inconsistent password policy | E2: =COUNTIF('Test Cases'!$K:$K,"*R01*")+COUNTIF('Test Cases'!$K:$K,"All") -> 42 | F2: AUTH-001, AUTH-002, AUTH-003, AUTH-004, AUTH-005, AUTH-006, AUTH-007, AUTH-008, AUTH-009, AUTH-010, AUTH-011, AUTH-012, AUTH-013, AUTH-014, AUTH-015, AUTH-016, AUTH-017, AUTH-018, AUTH-019, AUTH-020, AUTH-021, AUTH-022, AUTH-023, AUTH-024, AUTH-025, AAPI-001, AAPI-002, AAPI-003, AAPI-004, AAPI-005, AAPI-006, AAPI-007, AAPI-008, AAPI-009, REV-012, E2E-001, E2E-008, GAPI-001, GAPI-002, GAPI-003, GAPI-005, NFR-006
A3: R02 | B3: Dashboard | C3: High | D3: Incorrect records, filters, draft resume, user data isolation | E3: =COUNTIF('Test Cases'!$K:$K,"*R02*")+COUNTIF('Test Cases'!$K:$K,"All") -> 32 | F3: AUTH-023, AAPI-008, DASH-001, DASH-002, DASH-003, DASH-004, DASH-005, DASH-006, DASH-007, DASH-008, DASH-009, DASH-010, DASH-011, DASH-012, DASH-013, DASH-014, DASH-015, DASH-016, DAPI-001, DAPI-002, DAPI-003, DAPI-004, DAPI-005, DAPI-006, CAPI-007, DAPI2-004, STAT-006, SAPI-002, NAV-003, E2E-001, E2E-005, E2E-008
A4: R03 | B4: Client eligibility | C4: Critical | D4: Underage, over-age or future DOB accepted | E4: =COUNTIF('Test Cases'!$K:$K,"*R03*")+COUNTIF('Test Cases'!$K:$K,"All") -> 27 | F4: CLNT-001, CLNT-002, CLNT-003, CLNT-004, CLNT-005, CLNT-006, CLNT-007, CLNT-008, CLNT-009, CLNT-010, CLNT-011, CLNT-012, CLNT-013, CLNT-014, CLNT-015, CLNT-016, CLNT-017, CAPI-001, CAPI-002, CAPI-003, CAPI-004, CAPI-005, CAPI-006, CAPI-007, PROD-012, E2E-001, E2E-008
A5: R04 | B5: Address/contact | C5: High | D5: Invalid postal/email/phone accepted; copy-address error | E5: =COUNTIF('Test Cases'!$K:$K,"*R04*")+COUNTIF('Test Cases'!$K:$K,"All") -> 17 | F5: ADDR-001, ADDR-002, ADDR-003, ADDR-004, ADDR-005, ADDR-006, ADDR-007, ADDR-008, ADDR-009, ADDR-010, ADDR-011, ADDR-012, ACAPI-001, ACAPI-002, ACAPI-003, E2E-001, E2E-008
A6: R05 | B6: KYC/compliance | C6: Critical | D6: Evidence bypassed, sensitive ID exposed, PEP incomplete | E6: =COUNTIF('Test Cases'!$K:$K,"*R05*")+COUNTIF('Test Cases'!$K:$K,"All") -> 19 | F6: KYC-001, KYC-002, KYC-003, KYC-004, KYC-005, KYC-006, KYC-007, KYC-008, KYC-009, KYC-010, KYC-011, KYC-012, KYC-017, KAPI-001, KAPI-002, KAPI-004, DB-005, E2E-001, E2E-008
A7: R06 | B7: Financial suitability | C7: High | D7: Affordability/suitability rule not applied | E7: =COUNTIF('Test Cases'!$K:$K,"*R06*")+COUNTIF('Test Cases'!$K:$K,"All") -> 9 | F7: KYC-001, KYC-013, KYC-014, KYC-015, KYC-016, KAPI-003, KAPI-004, E2E-001, E2E-008
A8: R07 | B8: Product | C8: Critical | D8: Ineligible product/invalid face value accepted; premium stale | E8: =COUNTIF('Test Cases'!$K:$K,"*R07*")+COUNTIF('Test Cases'!$K:$K,"All") -> 24 | F8: CLNT-013, PROD-001, PROD-002, PROD-003, PROD-004, PROD-005, PROD-006, PROD-007, PROD-008, PROD-009, PROD-010, PROD-011, PROD-012, PROD-013, PAPI-001, PAPI-002, PAPI-003, PAPI-004, PAPI-005, RDR-001, RDR-012, RAPI-004, E2E-001, E2E-008
A9: R08 | B9: Riders | C9: Critical | D9: Coverage > base, age rule, count exceeded, incompatible riders | E9: =COUNTIF('Test Cases'!$K:$K,"*R08*")+COUNTIF('Test Cases'!$K:$K,"All") -> 21 | F9: RDR-001, RDR-002, RDR-003, RDR-004, RDR-005, RDR-006, RDR-007, RDR-008, RDR-009, RDR-010, RDR-011, RDR-012, RDR-013, RDR-014, RAPI-001, RAPI-002, RAPI-003, RAPI-004, E2E-001, E2E-002, E2E-008
A10: R09 | B10: Beneficiaries | C10: Critical | D10: Allocation not 100%, guardian missing, duplicate, removal invalid total | E10: =COUNTIF('Test Cases'!$K:$K,"*R09*")+COUNTIF('Test Cases'!$K:$K,"All") -> 29 | F10: BEN-001, BEN-002, BEN-003, BEN-004, BEN-005, BEN-006, BEN-007, BEN-008, BEN-009, BEN-010, BEN-011, BEN-012, BEN-013, BEN-014, BEN-015, BEN-016, BEN-017, BEN-018, BEN-019, BEN-020, BAPI-001, BAPI-002, BAPI-003, BAPI-004, BAPI-005, DB-003, E2E-001, E2E-002, E2E-008
A11: R10 | B11: Documents | C11: Critical | D11: Unsupported/oversized/missing files accepted; upload state wrong | E11: =COUNTIF('Test Cases'!$K:$K,"*R10*")+COUNTIF('Test Cases'!$K:$K,"All") -> 23 | F11: KYC-006, KYC-007, DOC-001, DOC-002, DOC-003, DOC-004, DOC-005, DOC-006, DOC-007, DOC-008, DOC-009, DOC-010, DOC-011, DOC-012, DOC-013, DOC-014, DOC-015, DAPI2-001, DAPI2-002, DAPI2-003, DAPI2-004, E2E-001, E2E-008
A12: R11 | B12: Review/submit | C12: Critical | D12: Errors not grouped, submit enabled wrongly, draft lost, submitted editable | E12: =COUNTIF('Test Cases'!$K:$K,"*R11*")+COUNTIF('Test Cases'!$K:$K,"All") -> 41 | F12: DASH-006, DASH-013, CLNT-016, CAPI-008, ADDR-012, KYC-017, PROD-013, RDR-013, BEN-019, DOC-009, DOC-015, REV-001, REV-002, REV-003, REV-004, REV-005, REV-006, REV-007, REV-009, REV-010, REV-011, REV-012, REV-013, REV-014, REV-015, RAPI2-001, RAPI2-002, RAPI2-003, RAPI2-004, RAPI2-005, RAPI2-006, DB-001, NAV-001, NAV-002, NAV-004, NAV-005, E2E-001, E2E-003, E2E-004, E2E-007, E2E-008
A13: R12 | B13: Status tracking | C13: High | D13: Reference missing or UI/backend status mismatch | E13: =COUNTIF('Test Cases'!$K:$K,"*R12*")+COUNTIF('Test Cases'!$K:$K,"All") -> 23 | F13: DASH-004, DASH-009, DASH-014, REV-007, REV-008, RAPI2-003, RAPI2-006, STAT-001, STAT-002, STAT-003, STAT-004, STAT-005, STAT-006, STAT-007, SAPI-001, SAPI-002, DB-002, DB-004, E2E-001, E2E-006, E2E-007, E2E-008, GAPI-004
A14: R13 | B14: Automation framework | C14: High | D14: Hard waits, unstable locators, shared state | E14: =COUNTIF('Test Cases'!$K:$K,"*R13*")+COUNTIF('Test Cases'!$K:$K,"All") -> 5 | F14: E2E-001, E2E-008, NFR-001, NFR-002, NFR-003
A15: R14 | B15: Environment/test data | C15: High | D15: Unavailable credentials, stale seed, config drift | E15: =COUNTIF('Test Cases'!$K:$K,"*R14*")+COUNTIF('Test Cases'!$K:$K,"All") -> 3 | F15: E2E-001, E2E-008, NFR-004
A16: R15 | B16: Evidence/reporting | C16: Medium | D16: Failure cannot be reproduced or classified | E16: =COUNTIF('Test Cases'!$K:$K,"*R15*")+COUNTIF('Test Cases'!$K:$K,"All") -> 4 | F16: E2E-001, E2E-008, GAPI-006, NFR-005

Sheet Open Items & Assumptions
A1: Ref | B1: Item | C1: Impact on test cases
A2: D-01/D-02 | B2: URL and seed users NOW supplied (see Test Data). MFA, admin, mentor users still not supplied. | C2: AUTH MFA case Blocked; role-permission cases cannot be written (D-09).
A3: D-04 | B3: Seeded defect catalog not supplied | C3: Cases cover every risk in Doc 04; map to defect IDs once catalog arrives.
A4: D-05 | B4: API schemas / endpoint paths not supplied | C4: API cases use documented service names and assumed paths; confirm before automation.
A5: D-06 | B5: Database access and queries not supplied | C5: DB-xxx cases remain Blocked.
A6: D-07 | B6: Product face-value limits, rider matrix, premium formula not supplied | C6: Boundary expected values stated as min/max; premium asserted by consistency (UI = API, direction of change) not absolute amounts.
A7: D-08 | B7: Mandatory documents, file-size limit, status transition matrix not supplied | C7: Document boundary and lifecycle cases need values.
A8: D-09 | B8: Role-permission matrix not supplied | C8: Only agent-level isolation tested.
A9: Clarif | B9: Lockout threshold, password policy, phone/postal/ID formats, duplicate beneficiary rule, 65-year inclusivity, trust/org beneficiaries | C9: Record observed behaviour during execution and raise as clarification where docs are silent.
A10: Assump | B10: Endpoint paths (e.g. /api/applications) are assumptions based on documented service groups | C10: Adjust once contract confirmed.
A11: Note | B11: Application was not reachable from the authoring environment; no case has been executed. Field labels are inferred from documents and must be validated against the real UI. | C11: All statuses = Not Run.
